Workbook

Sheet particle parameters
A1: JÖRMUNGANDR v.42
A2: Created by Dr. Marc Fries, Named by Mr. Wyatt Fries
A4: Starting at 0,0 final position is: | B4: Starting Position | E4: Displacement from Starting Position
A5: With wind: | B5: E | C5: N | H5: Terminus point
B6: 434097 | C6: 4577553 | E6: X (m) | F6: Y (m) | H6: 439034.5 | I6: 4590080.6
B7: End Position | C7: (UTM) | E7: ='lateral displacement'!AA12 -> 2927.6492 | F7: ='lateral displacement'!AC12 -> 8885.3942
B8: =B6+E7 -> 437024.65 | C8: =C6+F7 -> 4586438.4 | E8: X (mi) | F8: Y (mi)
B9: (Back-Calculation) | C9: (Back-Calculation) | E9: =E7*0.000621371192 -> 1.8191569 | F9: =F7*0.000621371192 -> 5.521128 | H9: m | I9: t
B10: =B6-E7 -> 431169.35 | C10: =C6-F7 -> 4568667.6 | H10: 10 | I10: 21
H11: 5 | I11: 25.7
A12: Total fall time | B12: ='vertical grid'!G13 -> 44.298438 | C12: s | D12: 217 | F12: volume (cm^3) | H12: 1 | I12: 38.3
A13: Max Fall Velocity (Vz): | B13: =Vz!AR4 -> 2555.1808 | C13: m/s | F13: =B21/$B$16 -> 301.20482 | H13: 0.5 | I13: 45.1
B14: =B13*2.2369363 -> 5715.7767 | C14: mph | F14: r (cm) | H14: 0.1 | I14: 64.5
F15: =(F13/4.1866667)^(1/3) -> 4.1590854
A16: Density | B16: 3.32 | C16: g/cm^3 | F16: r (m) | H16: 3000000 | I16: a
F17: =F15/100 -> 0.041590854 | H17: -4.108 | I17: b
A18: Low altitude value (bottom of range): | B18: 6670 | C18: m | F18: cross section (m^2)
A19: High altitude value (top of range): | B19: 16000 | C19: m | F19: =3.14*(F17^2) -> 0.0054315694 | H19: m | I19: t
H20: =H16*(I20^H17) -> 0.003964802 | I20: 145
A21: Meteorite mass | B21: 1000 | C21: g | E21: Typical density values (g/cc):
E22: H | F22: 3.4
E23: L | F23: 3.35
A24: Initial direction | B24: 3 | C24: compass degrees | E24: LL | F24: 3.21
A25: Initial velocity | B25: 3000 | C25: m/s | E25: (OC ave) | F25: 3.32
A26: Angle below horizontal | B26: 58.4 | E26: CI | F26: 2.11 | H26: 58.4 | I26: degrees in fireball
E27: CM | F27: 2.12
A28: Initial velocity | E28: CR | F28: 3.1
A29: X-Y Multiplier due to descent angle | B29: =COS(RADIANS(B26)) -> 0.52398591 | E29: CO | F29: 2.95
A30: Z multiplier | B30: =B33/B25 -> -0.85172693 | E30: CV | F30: 2.95
A31: Xi (m/s) | B31: =(SIN(RADIANS((B24)))*(B25*B29)) -> 82.26991 | E31: (CC ave) | F31: 3.01
A32: Yi (m/s) | B32: =(COS(RADIANS((B24)))*(B25*B29)) -> 1569.8034 | E32: EH | F32: 3.72
A33: Zi (m/s) | B33: =-(SIN(RADIANS(B26)))*B25 -> -2555.1808 | E33: EL | F33: 3.55
E34: (achondrites) | F34: 3.11
E35: Iron | F35: 7.5
A36: Sound travel time from terminus to ground | B36: =SUM(Vz!F:F) -> 96.276207 | C36: s | E36: Source:
A37: Use balloon data to the terminus altitude | B37: -OR- | E37: http://meteorites.wustl.edu/id/density.htm
B38: =ROUNDDOWN(B36/60,0) -> 1 | C38: min
B39: =B36-(B38*60) -> 36.276207 | C39: sec | E39: Average angle below horizontal
E40: 40.4 degrees
A41: Average speed of sound through column | B41: =AVERAGE(Vz!O:O) -> 318.85198 | C41: m/s
...

Sheet Timing Altitude
D1: Beam Width (deg) | H1: ` | O1: HH | P1: MM | Q1: SS
D2: 235.5m (short pulse) | N2: Fireball End | O2: 5 | P2: 50 | Q2: 15 | R2: assuming ~1s flight time to first radar return
A3: RADAR | B3: SWEEP | C3: Beam Angle (deg) | D3: 675 m (VCP 31 only) | E3: Est. Mass (g) | F3: Azimuth (deg) | G3: Distance (nmi) | H3: Refl Alt (m) | I3: Radar Alt (m) | J3: Ground Alt (m)* | K3: Refl AGL (m)* | L3: Refl ASL (m) | M3: Time from HDF (msec since midnight) | N3: s since midnight | O3: HH | P3: MM | Q3: SS | R3: Difference | S3: MM | T3: SS | U3: Area of return (m^2) | V3: n | W3: Meteorites per area (m^2) | X3: Per square 10m | Y3: Per square km | AA3: area of oval
R4: =($O$2*3600)+($P$2*60)+$Q$2 -> 21015 | S4: =ROUNDDOWN((R4/60),0) -> 350 | T4: =ROUNDDOWN(R4-(S4*60),1) -> 15 | AA4: long axis | AB4: 5850 | AC4: m
A5: KMKX 0546 | B5: 4.2 | C5: 0.96 | D5: 235.5 | E5: (all masses) | F5: 158 | G5: 97.024 | H5: 15258 | I5: 260 | J5: 218 | K5: =L5-J5 -> 15300 | L5: =H5+I5 -> 15518 | M5: 21016199 | N5: =M5/1000 -> 21016.199 | O5: =ROUNDDOWN(N5/(3600),0) -> 5 | P5: =ROUNDDOWN(((N5-(O5*3600))/60),0) -> 50 | Q5: =N5-(O5*3600)-(P5*60) -> 16.199 | R5: =ROUNDDOWN(N5-$R$4,0) -> 1 | S5: =ROUNDDOWN((R5/60),0) -> 0 | T5: =ROUNDDOWN(R5-(S5*60),1) -> 1
A6: KIND 0544 | B6: 2.48 | C6: 0.96 | D6: 235.5 | E6: 0.099 | F6: 329.5 | G6: 126.2 | H6: 13608 | I6: 216 | J6: 218 | K6: =L6-J6 -> 13606 | L6: =H6+I6 -> 13824 | M6: 21061743 | N6: =M6/1000 -> 21061.743 | O6: =ROUNDDOWN(N6/(3600),0) -> 5 | P6: =ROUNDDOWN(((N6-(O6*3600))/60),0) -> 51 | Q6: =N6-(O6*3600)-(P6*60) -> 1.743 | R6: =ROUNDDOWN(N6-$R$4,0) -> 46 | S6: =ROUNDDOWN((R6/60),0) -> 0 | T6: =ROUNDDOWN(R6-(S6*60),1) -> 46 | W6: =V6/U6 -> #DIV/0! | X6: =W6*100 -> #DIV/0! | Y6: =W6*1000000 -> #DIV/0! | AA6: short axis | AB6: 1185 | AC6: m
A7: KIWX 0548 | B7: 2.38 | C7: 0.96 | D7: 235.5 | E7: 7.9 | F7: 277.25 | G7: 91.601 | H7: 8929 | I7: 260 | J7: 218 | K7: =L7-J7 -> 8971 | L7: =H7+I7 -> 9189 | M7: 21091876 | N7: =M7/1000 -> 21091.876 | O7: =ROUNDDOWN(N7/(3600),0) -> 5 | P7: =ROUNDDOWN(((N7-(O7*3600))/60),0) -> 51 | Q7: =N7-(O7*3600)-(P7*60) -> 31.876 | R7: =ROUNDDOWN(N7-$R$4,0) -> 76 | S7: =ROUNDDOWN((R7/60),0) -> 1 | T7: =ROUNDDOWN(R7-(S7*60),1) -> 16 | W7: =V7/U7 -> #DIV/0! | X7: =W7*100 -> #DIV/0! | Y7: =W7*1000000 -> #DIV/0! | AA7: area | AB7: =PI()*(AB6/2)*(AB5/2) -> 0 | AC7: m^2
A8: KILX 0544 | B8: 3.39 | C8: 0.96 | D8: 235.5 | E8: 0.009 | F8: 43 | G8: 108.508 | H8: 14501 | I8: 194 | J8: 218 | K8: =L8-J8 -> 14477 | L8: =H8+I8 -> 14695 | M8: 21106310 | N8: =M8/1000 -> 21106.31 | O8: =ROUNDDOWN(N8/(3600),0) -> 5 | P8: =ROUNDDOWN(((N8-(O8*3600))/60),0) -> 51 | Q8: =N8-(O8*3600)-(P8*60) -> 46.31 | R8: =ROUNDDOWN(N8-$R$4,0) -> 91 | S8: =ROUNDDOWN((R8/60),0) -> 1 | T8: =ROUNDDOWN(R8-(S8*60),1) -> 31 | W8: =V8/U8 -> #DIV/0! | X8: =W8*100 -> #DIV/0! | Y8: =W8*1000000 -> #DIV/0!
A9: KLOT 0547 | B9: 9.91 | C9: 0.96 | D9: 235.5 | E9: 36 | F9: 112 | G9: 20.053 | H9: 6449 | I9: 221 | J9: 218 | K9: =L9-J9 -> 6452 | L9: =H9+I9 -> 6670 | M9: 21106429 | N9: =M9/1000 -> 21106.429 | O9: =ROUNDDOWN(N9/(3600),0) -> 5 | P9: =ROUNDDOWN(((N9-(O9*3600))/60),0) -> 51 | Q9: =N9-(O9*3600)-(P9*60) -> 46.429 | R9: =ROUNDDOWN(N9-$R$4,0) -> 91 | S9: =ROUNDDOWN((R9/60),0) -> 1 | T9: =ROUNDDOWN(R9-(S9*60),1) -> 31 | W9: =V9/U9 -> #DIV/0! | X9: =W9*100 -> #DIV/0! | Y9: =W9*1000000 -> #DIV/0!
A10: KIWX 0548 | B10: 3.39 | C10: 0.96 | D10: 235.5 | E10: 0.07 | F10: 276 | G10: 91.803 | H10: 11914 | I10: 260 | J10: 218 | K10: =L10-J10 -> 11956 | L10: =H10+I10 -> 12174 | M10: 21124936 | N10: =M10/1000 -> 21124.936 | O10: =ROUNDDOWN(N10/(3600),0) -> 5 | P10: =ROUNDDOWN(((N10-(O10*3600))/60),0) -> 52 | Q10: =N10-(O10*3600)-(P10*60) -> 4.936 | R10: =ROUNDDOWN(N10-$R$4,0) -> 109 | S10: =ROUNDDOWN((R10/60),0) -> 1 | T10: =ROUNDDOWN(R10-(S10*60),1) -> 49 | W10: =V10/U10 -> #DIV/0! | X10: =W10*100 -> #DIV/0! | Y10: =W10*1000000 -> #DIV/0!
A11: KGRR 0550 | B11: 1.5 | C11: 0.96 | D11: 235.5 | E11: 0.388 | F11: 230 | G11: 128.084 | H11: 9854 | I11: 244 | J11: 218 | K11: =L11-J11 -> 9880 | L11: =H11+I11 -> 10098 | M11: 21128113 | N11: =M11/1000 -> 21128.113 | O11: =ROUNDDOWN(N11/(3600),0) -> 5 | P11: =ROUNDDOWN(((N11-(O11*3600))/60),0) -> 52 | Q11: =N11-(O11*3600)-(P11*60) -> 8.113 | R11: =ROUNDDOWN(N11-$R$4,0) -> 113 | S11: =ROUNDDOWN((R11/60),0) -> 1 | T11: =ROUNDDOWN(R11-(S11*60),1) -> 53 | W11: =V11/U11 -> #DIV/0! | X11: =W11*100 -> #DIV/0! | Y11: =W11*1000000 -> #DIV/0!
A12: KLOT 0547 | B12: 14.62 | C12: 0.96 | D12: 235.5 | E12: 0.46 | F12: 114.5 | G12: 20.037 | H12: 9498 | I12: 221 | J12: 218 | K12: =L12-J12 -> 9501 | L12: =H12+I12 -> 9719 | M12: 21133554 | N12: =M12/1000 -> 21133.554 | O12: =ROUNDDOWN(N12/(3600),0) -> 5 | P12: =ROUNDDOWN(((N12-(O12*3600))/60),0) -> 52 | Q12: =N12-(O12*3600)-(P12*60) -> 13.554 | R12: =ROUNDDOWN(N12-$R$4,0) -> 118 | S12: =ROUNDDOWN((R12/60),0) -> 1 | T12: =ROUNDDOWN(R12-(S12*60),1) -> 58 | W12: =V12/U12 -> #DIV/0! | X12: =W12*100 -> #DIV/0! | Y12: =W12*1000000 -> #DIV/0!
A13: KLOT 0547 | B13: 19.49 | C13: 0.96 | D13: 235.5 | E13: 0.004 | F13: 118.5 | G13: 20.57 | H13: 12780 | I13: 221 | J13: 218 | K13: =L13-J13 -> 12783 | L13: =H13+I13 -> 13001 | M13: 21160539 | N13: =M13/1000 -> 21160.539 | O13: =ROUNDDOWN(N13/(3600),0) -> 5 | P13: =ROUNDDOWN(((N13-(O13*3600))/60),0) -> 52 | Q13: =N13-(O13*3600)-(P13*60) -> 40.539 | R13: =ROUNDDOWN(N13-$R$4,0) -> 145 | S13: =ROUNDDOWN((R13/60),0) -> 2 | T13: =ROUNDDOWN(R13-(S13*60),1) -> 25 | W13: =V13/U13 -> #DIV/0! | X13: =W13*100 -> #DIV/0! | Y13: =W13*1000000 -> #DIV/0!
A14: KMKX 0552 | B14: 1.43 | C14: 0.96 | D14: 235.5 | E14: 0.23 | F14: 156 | G14: 99.694 | H14: 6834 | I14: 260 | J14: 218 | K14: =L14-J14 -> 6876 | L14: =H14+I14 -> 7094 | M14: 21232616 | N14: =M14/1000 -> 21232.616 | O14: =ROUNDDOWN(N14/(3600),0) -> 5 | P14: =ROUNDDOWN(((N14-(O14*3600))/60),0) -> 53 | Q14: =N14-(O14*3600)-(P14*60) -> 52.616 | R14: =ROUNDDOWN(N14-$R$4,0) -> 217 | S14: =ROUNDDOWN((R14/60),0) -> 3 | T14: =ROUNDDOWN(R14-(S14*60),1) -> 37
A15: KLOT 0553 | B15: 5.99 | C15: 0.96 | D15: 235.5 | E15: 0.051 | F15: 116.5 | G15: 24.095 | H15: 4769 | I15: 221 | J15: 218 | K15: =L15-J15 -> 4772 | L15: =H15+I15 -> 4990 | M15: 21426860 | N15: =M15/1000 -> 21426.86 | O15: =ROUNDDOWN(N15/(3600),0) -> 5 | P15: =ROUNDDOWN(((N15-(O15*3600))/60),0) -> 57 | Q15: =N15-(O15*3600)-(P15*60) -> 6.86 | R15: =ROUNDDOWN(N15-$R$4,0) -> 411 | S15: =ROUNDDOWN((R15/60),0) -> 6 | T15: =ROUNDDOWN(R15-(S15*60),1) -> 51 | W15: =V15/U15 -> #DIV/0! | X15: =W15*100 -> #DIV/0! | Y15: =W15*1000000 -> #DIV/0!
A16: KIWX 0554 | B16: 2.38 | C16: 0.96 | D16: 235.5 | E16: 0.001 | F16: 267 | G16: 93.57 | H16: 9141 | I16: 260 | J16: 218 | K16: =L16-J16 -> 9183 | L16: =H16+I16 -> 9401 | M16: 21440510 | N16: =M16/1000 -> 21440.51 | O16: =ROUNDDOWN(N16/(3600),0) -> 5 | P16: =ROUNDDOWN(((N16-(O16*3600))/60),0) -> 57 | Q16: =N16-(O16*3600)-(P16*60) -> 20.51 | R16: =ROUNDDOWN(N16-$R$4,0) -> 425 | S16: =ROUNDDOWN((R16/60),0) -> 7 | T16: =ROUNDDOWN(R16-(S16*60),1) -> 5 | W16: =V16/U16 -> #DIV/0! | X16: =W16*100 -> #DIV/0! | Y16: =W16*1000000 -> #DIV/0!
A17: KLOT 0553 | B17: 9.91 | C17: 0.96 | D17: 235.5 | E17: 0.002 | F17: 117.5 | G17: 24.34 | H17: 7881 | I17: 221 | J17: 218 | K17: =L17-J17 -> 7884 | L17: =H17+I17 -> 8102 | M17: 21458541 | N17: =M17/1000 -> 21458.541 | O17: =ROUNDDOWN(N17/(3600),0) -> 5 | P17: =ROUNDDOWN(((N17-(O17*3600))/60),0) -> 57 | Q17: =N17-(O17*3600)-(P17*60) -> 38.541 | R17: =ROUNDDOWN(N17-$R$4,0) -> 443 | S17: =ROUNDDOWN((R17/60),0) -> 7 | T17: =ROUNDDOWN(R17-(S17*60),1) -> 23 | W17: =V17/U17 -> #DIV/0! | X17: =W17*100 -> #DIV/0! | Y17: =W17*1000000 -> #DIV/0!
K18: =L18-J18 -> 0 | L18: =H18+I18 -> 0 | N18: =M18/1000 -> 0 | O18: =ROUNDDOWN(N18/(3600),0) -> 0 | P18: =ROUNDDOWN(((N18-(O18*3600))/60),0) -> 0 | Q18: =N18-(O18*3600)-(P18*60) -> 0 | R18: =ROUNDDOWN(N18-$R$4,0) -> -21015 | S18: =ROUNDDOWN((R18/60),0) -> -350 | T18: =ROUNDDOWN(R18-(S18*60),1) -> -15
K19: =L19-J19 -> 0 | L19: =H19+I19 -> 0 | N19: =M19/1000 -> 0 | O19: =ROUNDDOWN(N19/(3600),0) -> 0 | P19: =ROUNDDOWN(((N19-(O19*3600))/60),0) -> 0 | Q19: =N19-(O19*3600)-(P19*60) -> 0 | R19: =ROUNDDOWN(N19-$R$4,0) -> -21015 | S19: =ROUNDDOWN((R19/60),0) -> -350 | T19: =ROUNDDOWN(R19-(S19*60),1) -> -15
K20: =L20-J20 -> 0 | L20: =H20+I20 -> 0 | N20: =M20/1000 -> 0 | O20: =ROUNDDOWN(N20/(3600),0) -> 0 | P20: =ROUNDDOWN(((N20-(O20*3600))/60),0) -> 0 | Q20: =N20-(O20*3600)-(P20*60) -> 0 | R20: =ROUNDDOWN(N20-$R$4,0) -> -21015 | S20: =ROUNDDOWN((R20/60),0) -> -350 | T20: =ROUNDDOWN(R20-(S20*60),1) -> -15
K21: =L21-J21 -> 0 | L21: =H21+I21 -> 0 | N21: =M21/1000 -> 0 | O21: =ROUNDDOWN(N21/(3600),0) -> 0 | P21: =ROUNDDOWN(((N21-(O21*3600))/60),0) -> 0 | Q21: =N21-(O21*3600)-(P21*60) -> 0 | R21: =ROUNDDOWN(N21-$R$4,0) -> -21015 | S21: =ROUNDDOWN((R21/60),0) -> -350 | T21: =ROUNDDOWN(R21-(S21*60),1) -> -15
A22: uncertain | K22: =L22-J22 -> 0 | L22: =H22+I22 -> 0 | N22: =M22/1000 -> 0 | O22: =ROUNDDOWN(N22/(3600),0) -> 0 | P22: =ROUNDDOWN(((N22-(O22*3600))/60),0) -> 0 | Q22: =N22-(O22*3600)-(P22*60) -> 0 | R22: =ROUNDDOWN(N22-$R$4,0) -> -21015 | S22: =ROUNDDOWN((R22/60),0) -> -350 | T22: =ROUNDDOWN(R22-(S22*60),1) -> -15
K23: =L23-J23 -> 0 | L23: =H23+I23 -> 0 | N23: =M23/1000 -> 0 | O23: =ROUNDDOWN(N23/(3600),0) -> 0 | P23: =ROUNDDOWN(((N23-(O23*3600))/60),0) -> 0 | Q23: =N23-(O23*3600)-(P23*60) -> 0 | R23: =ROUNDDOWN(N23-$R$4,0) -> -21015 | S23: =ROUNDDOWN((R23/60),0) -> -350 | T23: =ROUNDDOWN(R23-(S23*60),1) -> -15
K24: =L24-J24 -> 0 | L24: =H24+I24 -> 0 | N24: =M24/1000 -> 0 | O24: =ROUNDDOWN(N24/(3600),0) -> 0 | P24: =ROUNDDOWN(((N24-(O24*3600))/60),0) -> 0 | Q24: =N24-(O24*3600)-(P24*60) -> 0 | R24: =ROUNDDOWN(N24-$R$4,0) -> -21015 | S24: =ROUNDDOWN((R24/60),0) -> -350 | T24: =ROUNDDOWN(R24-(S24*60),1) -> -15
Z27: y=3246.4x^-1.818
Z28: Mass (g) | AA28: Density (calc, meteorites per sq km) | AE28: Mets per sq 10m
Z29: 0.1 | AA29: =3246.4*(Z29^-1.818) -> 213502.04 | AE29: =AA29*0.0001 -> 21.350204
Z30: 1 | AA30: =3246.4*(Z30^-1.818) -> 3246.4 | AE30: =AA30*0.0001 -> 0.32464
Z31: 5 | AA31: =3246.4*(Z31^-1.818) -> 174.05021 | AE31: =AA31*0.0001 -> 0.017405021
Z32: 10 | AA32: =3246.4*(Z32^-1.818) -> 49.363055 | AE32: =AA32*0.0001 -> 0.0049363055
Z33: 50 | AA33: =3246.4*(Z33^-1.818) -> 2.6465162 | AE33: =AA33*0.0001 -> 0.00026465162
Z34: 100 | AA34: =3246.4*(Z34^-1.818) -> 0.75058871 | AE34: =AA34*0.0001 -> 7.5058871e-05
Z35: 500 | AA35: =3246.4*(Z35^-1.818) -> 0.040241537 | AE35: =AA35*0.0001 -> 4.0241537e-06
Z36: 1000 | AA36: =3246.4*(Z36^-1.818) -> 0.011413058 | AE36: =AA36*0.0001 -> 1.1413058e-06
Z37: 5000 | AA37: =3246.4*(Z37^-1.818) -> 0.0006118917 | AE37: =AA37*0.0001 -> 6.118917e-08
Z38: 10000 | AA38: =3246.4*(Z38^-1.818) -> 0.00017354097 | AE38: =AA38*0.0001 -> 1.7354097e-08

Sheet Sound Travel
A1: Seismometer geometry | B1: a: Length along ground (m) | C1: b: Altitude (m) | D1: c: Hypoteneuse (m) | E1: Actual multiple | F1: theta (deg) | G1: sin theta | I1: Altitude | K1: delta-Altitude | L1: =IF('vertical grid'!B1>($C$2),0,'vertical grid'!D1) -> 25.333333 | M1: end of data | N1: 0 | O1: Speed of sound | P1: =N1*Y1 -> 0 | Q1: Slant distance per altitude segment | R1: First seismometer | S1: =L1/$G$2 -> 124.21086 | T1: Second seismometer | U1: =L1/$G$3 -> 50.35121 | V1: Third seismometer | W1: =L1/$G$4 -> 74.824028 | X1: Speed of sound | Y1: =Vz!O1 -> 339.21061 | Z1: Time per slant distance | AB1: First seismometer | AC1: =S1/Y1 -> 0.36617622 | AD1: Total time | AE1: =SUM(AC1:AC600)+AA25 -> 569.96801 | AF1: Second seismometer | AG1: =U1/Y1 -> 0.14843642 | AH1: Total time | AI1: =SUM(AG1:AG600)+AA26 -> 231.04726 | AJ1: Third seismometer | AK1: =W1/Y1 -> 0.2205828 | AL1: Total time | AM1: =SUM(AK1:AK600)+AA26 -> 324.05318
B2: 168000 | C2: 35000 | D2: =SQRT((C2*C2)+(B2*B2)) -> 171607.11 | E2: =D2/D2 -> 1 | F2: =DEGREES(ACOS(B2/D2)) -> 11.768289 | G2: =C2/D2 -> 0.20395425 | I2: (m) | K2: (m) | L2: =IF('vertical grid'!B2>($C$2),0,'vertical grid'!D2) -> 25.333333 | N2: =IF(L3=0,IF(L2>0,1,0),0) -> 0 | O2: EOF tally (m/s) | P2: =N2*Y2 -> 0 | Q2: (m) | S2: =L2/$G$2 -> 124.21086 | U2: =L2/$G$3 -> 50.35121 | W2: =L2/$G$4 -> 74.824028 | X2: (m/s) | Y2: =Vz!O2 -> 338.79575 | Z2: (s) | AC2: =S2/Y2 -> 0.36662462 | AD2: (s) | AG2: =U2/Y2 -> 0.14861819 | AH2: (s) | AK2: =W2/Y2 -> 0.22085291 | AL2: (s)
B3: 60118 | C3: - | D3: =SQRT((C2*C2)+(B3*B3)) -> 69564.171 | E3: =D3/D2 -> 0.40536882 | F3: =DEGREES(ACOS(B3/D3)) -> 30.207466 | G3: =C2/D3 -> 0.50313257 | L3: =IF('vertical grid'!B3>($C$2),0,'vertical grid'!D3) -> 25.333333 | N3: =IF(L4=0,IF(L3>0,1,0),0) -> 0 | P3: =N3*Y3 -> 0 | S3: =L3/$G$2 -> 124.21086 | U3: =L3/$G$3 -> 50.35121 | W3: =L3/$G$4 -> 74.824028 | Y3: =Vz!O3 -> 338.79575 | AC3: =S3/Y3 -> 0.36662462 | AG3: =U3/Y3 -> 0.14861819 | AK3: =W3/Y3 -> 0.22085291
B4: 97270 | C4: - | D4: =SQRT((C2*C2)+(B4*B4)) -> 103375.3 | E4: =D4/D2 -> 0.60239521 | F4: =DEGREES(ACOS(B4/D4)) -> 19.789907 | G4: =C2/D4 -> 0.33857217 | K4: Total alt | L4: =IF('vertical grid'!B4>($C$2),0,'vertical grid'!D4) -> 25.333333 | N4: =IF(L5=0,IF(L4>0,1,0),0) -> 0 | O4: Speed of sound at | P4: =N4*Y4 -> 0 | Q4: Total slant distance (km) | S4: =L4/$G$2 -> 124.21086 | U4: =L4/$G$3 -> 50.35121 | W4: =L4/$G$4 -> 74.824028 | Y4: =Vz!O4 -> 338.79575 | Z4: Missing due to sampling | AC4: =S4/Y4 -> 0.36662462 | AG4: =U4/Y4 -> 0.14861819 | AK4: =W4/Y4 -> 0.22085291
K5: (km) | L5: =IF('vertical grid'!B5>($C$2),0,'vertical grid'!D5) -> 101.66667 | N5: =IF(L6=0,IF(L5>0,1,0),0) -> 0 | O5: fireball terminus (m/s) | P5: =N5*Y5 -> 0 | S5: =L5/$G$2 -> 498.47779 | U5: =L5/$G$3 -> 202.06735 | W5: =L5/$G$4 -> 300.28064 | Y5: =Vz!O5 -> 337.13118 | Z5: error in RAOB (m) | AC5: =S5/Y5 -> 1.478587 | AD5: Min | AE5: =ROUNDDOWN(AE1/60,0) -> 9 | AG5: =U5/Y5 -> 0.59937308 | AH5: Min | AI5: =ROUNDDOWN(AI1/60,0) -> 3 | AK5: =W5/Y5 -> 0.89069375 | AL5: Min | AM5: =ROUNDDOWN(AM1/60,0) -> 5
A6: Arrival time at seismometers | G6: Distance along | L6: =IF('vertical grid'!B6>($C$2),0,'vertical grid'!D6) -> 101.66667 | N6: =IF(L7=0,IF(L6>0,1,0),0) -> 0 | P6: =N6*Y6 -> 0 | Q6: First seismometer | R6: =K7/G2 -> 142.46986 | S6: =L6/$G$2 -> 498.47779 | U6: =L6/$G$3 -> 202.06735 | W6: =L6/$G$4 -> 300.28064 | Y6: =Vz!O6 -> 337.13118 | Z6: First seismometer | AA6: =D2-(R6*1000) -> 29137.253 | AC6: =S6/Y6 -> 1.478587 | AG6: =U6/Y6 -> 0.59937308 | AK6: =W6/Y6 -> 0.89069375
A7: (nearest seismometer first) | E7: Total sec since | F7: Arrival time | G7: ground first | K7: =(SUM(L1:L600)/1000) -> 29.057333 | L7: =IF('vertical grid'!B7>($C$2),0,'vertical grid'!D7) -> 101.66667 | N7: =IF(L8=0,IF(L7>0,1,0),0) -> 0 | O7: =SUM(P1:P600) -> 297.56193 | P7: =N7*Y7 -> 0 | Q7: Second seismometer | R7: =K7/G3 -> 57.752838 | S7: =L7/$G$2 -> 498.47779 | U7: =L7/$G$3 -> 202.06735 | W7: =L7/$G$4 -> 300.28064 | Y7: =Vz!O7 -> 337.13118 | Z7: Second seismometer | AA7: =D3-(R7*1000) -> 11811.334 | AC7: =S7/Y7 -> 1.478587 | AD7: Sec | AE7: =AE1-(AE5*60) -> 29.968006 | AG7: =U7/Y7 -> 0.59937308 | AH7: Sec | AI7: =AI1-(AI5*60) -> 51.047258 | AK7: =W7/Y7 -> 0.89069375 | AL7: Sec | AM7: =AM1-(AM5*60) -> 24.053181
B8: HH | C8: MM | D8: SS | E8: midnight | F8: multipler | G8: Estimate (km) | L8: =IF('vertical grid'!B8>($C$2),0,'vertical grid'!D8) -> 55.333333 | N8: =IF(L9=0,IF(L8>0,1,0),0) -> 0 | P8: =N8*Y8 -> 0 | Q8: Third seismometer | R8: =K7/G4 -> 85.82316 | S8: =L8/$G$2 -> 271.30267 | U8: =L8/$G$3 -> 109.97764 | W8: =L8/$G$4 -> 163.43143 | Y8: =Vz!O8 -> 336.23606 | Z8: Third seismometer | AA8: =D4-(R8*1000) -> 17552.142 | AC8: =S8/Y8 -> 0.80688153 | AG8: =U8/Y8 -> 0.32708461 | AK8: =W8/Y8 -> 0.48606157
A9: G65A | B9: 1 | C9: 15 | D9: 10 | E9: =D9+(C9*60)+(B9*3600) -> 4510 | F9: 1 | G9: =(F9*(SQRT(D2^2-$C$2^2)))/1000 -> 168 | L9: =IF('vertical grid'!B9>($C$2),0,'vertical grid'!D9) -> 55.333333 | N9: =IF(L10=0,IF(L9>0,1,0),0) -> 0 | O9: Average speed of sound | P9: =N9*Y9 -> 0 | S9: =L9/$G$2 -> 271.30267 | U9: =L9/$G$3 -> 109.97764 | W9: =L9/$G$4 -> 163.43143 | Y9: =Vz!O9 -> 336.23606 | AC9: =S9/Y9 -> 0.80688153 | AG9: =U9/Y9 -> 0.32708461 | AK9: =W9/Y9 -> 0.48606157
C10: 5 | D10: 59 | E10: =D10+(C10*60)+(B10*3600) -> 359 | F10: =AI1/AE1 -> 0.40536882 | G10: =(SQRT(D3^2-$C$2^2))/1000 -> 60.118 | L10: =IF('vertical grid'!B10>($C$2),0,'vertical grid'!D10) -> 55.333333 | N10: =IF(L11=0,IF(L10>0,1,0),0) -> 0 | O10: (m/s) | P10: =N10*Y10 -> 0 | S10: =L10/$G$2 -> 271.30267 | U10: =L10/$G$3 -> 109.97764 | W10: =L10/$G$4 -> 163.43143 | Y10: =Vz!O10 -> 336.23606 | Z10: Total distance (m) | AC10: =S10/Y10 -> 0.80688153 | AG10: =U10/Y10 -> 0.32708461 | AK10: =W10/Y10 -> 0.48606157
E11: =D11+(C11*60)+(B11*3600) -> 0 | F11: =AM1/AE1 -> 0.56854627 | G11: =(SQRT(D4^2-$C$2^2))/1000 -> 97.27 | L11: =IF('vertical grid'!B11>($C$2),0,'vertical grid'!D11) -> 46 | N11: =IF(L12=0,IF(L11>0,1,0),0) -> 0 | O11: =AVERAGE(Y1:Y600) -> 318.85198 | P11: =N11*Y11 -> 0 | S11: =L11/$G$2 -> 225.54077 | U11: =L11/$G$3 -> 91.427197 | W11: =L11/$G$4 -> 135.86468 | Y11: =Vz!O11 -> 335.39846 | Z11: First seismometer | AA11: =AA6+(R6*1000) -> 171607.11 | AC11: =S11/Y11 -> 0.67245619 | AG11: =U11/Y11 -> 0.27259277 | AK11: =W11/Y11 -> 0.40508439
L12: =IF('vertical grid'!B12>($C$2),0,'vertical grid'!D12) -> 46 | N12: =IF(L13=0,IF(L12>0,1,0),0) -> 0 | P12: =N12*Y12 -> 0 | S12: =L12/$G$2 -> 225.54077 | U12: =L12/$G$3 -> 91.427197 | W12: =L12/$G$4 -> 135.86468 | Y12: =Vz!O12 -> 335.39846 | Z12: Second seismometer | AA12: =AA7+(R7*1000) -> 69564.171 | AC12: =S12/Y12 -> 0.67245619 | AG12: =U12/Y12 -> 0.27259277 | AK12: =W12/Y12 -> 0.40508439
A13: Calculated fireball time | E13: Total sec since | F13: Variance from | G13: Equivalent | L13: =IF('vertical grid'!B13>($C$2),0,'vertical grid'!D13) -> 46 | N13: =IF(L14=0,IF(L13>0,1,0),0) -> 0 | P13: =N13*Y13 -> 0 | S13: =L13/$G$2 -> 225.54077 | U13: =L13/$G$3 -> 91.427197 | W13: =L13/$G$4 -> 135.86468 | Y13: =Vz!O13 -> 335.39846 | Z13: Third seismometer | AA13: =AA8+(R8*1000) -> 103375.3 | AC13: =S13/Y13 -> 0.67245619 | AG13: =U13/Y13 -> 0.27259277 | AK13: =W13/Y13 -> 0.40508439
B14: HH | C14: MM | D14: SS | E14: midnight | F14: Mean (s) | G14: Dist (est) (m) | L14: =IF('vertical grid'!B14>($C$2),0,'vertical grid'!D14) -> 101.66667 | N14: =IF(L15=0,IF(L14>0,1,0),0) -> 0 | P14: =N14*Y14 -> 0 | S14: =L14/$G$2 -> 498.47779 | U14: =L14/$G$3 -> 202.06735 | W14: =L14/$G$4 -> 300.28064 | Y14: =Vz!O14 -> 333.53629 | AC14: =S14/Y14 -> 1.4945234 | AG14: =U14/Y14 -> 0.60583319 | AK14: =W14/Y14 -> 0.90029374
B15: =ROUNDDOWN(E15/3600,0) -> 1 | C15: =ROUNDDOWN((E15-(B15*3600))/60,0) -> 5 | D15: =ROUNDDOWN(E15-((B15*3600)+(C15*60)),1) -> 40 | E15: =E9-AE1 -> 3940.032 | F15: =(AVERAGE(E15:E17)-E15) -> -2692.0548 | G15: =F15*O11 -> -858367 | H15: =B2-G15 -> 1026367 | J15: =D2/O11 -> 538.20306 | L15: =IF('vertical grid'!B15>($C$2),0,'vertical grid'!D15) -> 101.66667 | N15: =IF(L16=0,IF(L15>0,1,0),0) -> 0 | P15: =N15*Y15 -> 0 | S15: =L15/$G$2 -> 498.47779 | U15: =L15/$G$3 -> 202.06735 | W15: =L15/$G$4 -> 300.28064 | Y15: =Vz!O15 -> 333.53629 | Z15: Difference from | AC15: =S15/Y15 -> 1.4945234 | AG15: =U15/Y15 -> 0.60583319 | AK15: =W15/Y15 -> 0.90029374
B16: =ROUNDDOWN(E16/3600,0) -> 0 | C16: =ROUNDDOWN((E16-(B16*3600))/60,0) -> 2 | D16: =ROUNDDOWN(E16-((B16*3600)+(C16*60)),1) -> 7.9 | E16: =E10-AI1 -> 127.95274 | F16: =(AVERAGE(E15:E17)-E16) -> 1120.0244 | G16: =F16*O11 -> 357122.01 | H16: =B3-G16 -> -297004.01 | J16: =J15/60 -> 8.970051 | K16: min | L16: =IF('vertical grid'!B16>($C$2),0,'vertical grid'!D16) -> 101.66667 | N16: =IF(L17=0,IF(L16>0,1,0),0) -> 0 | P16: =N16*Y16 -> 0 | S16: =L16/$G$2 -> 498.47779 | U16: =L16/$G$3 -> 202.06735 | W16: =L16/$G$4 -> 300.28064 | Y16: =Vz!O16 -> 333.53629 | Z16: hypoteneuse (m) | AC16: =S16/Y16 -> 1.4945234 | AG16: =U16/Y16 -> 0.60583319 | AK16: =W16/Y16 -> 0.90029374
B17: =ROUNDDOWN(E17/3600,0) -> 0 | C17: =ROUNDDOWN((E17-(B17*3600))/60,0) -> -5 | D17: =ROUNDDOWN(E17-((B17*3600)+(C17*60)),1) -> -24 | E17: =E11-AM1 -> -324.05318 | F17: =(AVERAGE(E15:E17)-E17) -> 1572.0304 | G17: =F17*O11 -> 501244.99 | H17: =B4-G17 -> -403974.99 | J17: =J15-(9*60) -> -1.7969415 | K17: sec | L17: =IF('vertical grid'!B17>($C$2),0,'vertical grid'!D17) -> 82 | N17: =IF(L18=0,IF(L17>0,1,0),0) -> 0 | P17: =N17*Y17 -> 0 | S17: =L17/$G$2 -> 402.05094 | U17: =L17/$G$3 -> 162.97892 | W17: =L17/$G$4 -> 242.19356 | Y17: =Vz!O17 -> 332.02693 | Z17: First seismometer | AA17: =AA11-D2 -> 0 | AC17: =S17/Y17 -> 1.2108986 | AG17: =U17/Y17 -> 0.49086053 | AK17: =W17/Y17 -> 0.72943951
L18: =IF('vertical grid'!B18>($C$2),0,'vertical grid'!D18) -> 82 | N18: =IF(L19=0,IF(L18>0,1,0),0) -> 0 | P18: =N18*Y18 -> 0 | S18: =L18/$G$2 -> 402.05094 | U18: =L18/$G$3 -> 162.97892 | W18: =L18/$G$4 -> 242.19356 | Y18: =Vz!O18 -> 332.02693 | Z18: Second seismometer | AA18: =AA12-D3 -> 0 | AC18: =S18/Y18 -> 1.2108986 | AG18: =U18/Y18 -> 0.49086053 | AK18: =W18/Y18 -> 0.72943951
D19: Variance in time values | E19: =MAX(E15:E17)-MIN(E15:E17) -> 4264.0852 | F19: s | H19: 54318.508 | L19: =IF('vertical grid'!B19>($C$2),0,'vertical grid'!D19) -> 82 | N19: =IF(L20=0,IF(L19>0,1,0),0) -> 0 | P19: =N19*Y19 -> 0 | S19: =L19/$G$2 -> 402.05094 | U19: =L19/$G$3 -> 162.97892 | W19: =L19/$G$4 -> 242.19356 | Y19: =Vz!O19 -> 332.02693 | Z19: Third seismometer | AA19: =AA13-D4 -> 0 | AC19: =S19/Y19 -> 1.2108986 | AG19: =U19/Y19 -> 0.49086053 | AK19: =W19/Y19 -> 0.72943951
D20: Distance equivalent (est) | E20: =E19*O11 -> 1359612 | F20: m | H20: 63844.534 | L20: =IF('vertical grid'!B20>($C$2),0,'vertical grid'!D20) -> 19.666667 | N20: =IF(L21=0,IF(L20>0,1,0),0) -> 0 | P20: =N20*Y20 -> 0 | S20: =L20/$G$2 -> 96.426852 | U20: =L20/$G$3 -> 39.088439 | W20: =L20/$G$4 -> 58.087074 | Y20: =Vz!O20 -> 331.7848 | AC20: =S20/Y20 -> 0.29063071 | AG20: =U20/Y20 -> 0.11781263 | AK20: =W20/Y20 -> 0.17507455
A21: Calculated fireball time | B21: =ROUNDDOWN(E21/3600,0) -> 0 | C21: =ROUNDDOWN((E21-(B21*3600))/60,0) -> 20 | D21: =ROUNDDOWN(E21-((B21*3600)+(C21*60)),1) -> 47.9 | E21: =AVERAGE(E15:E17) -> 1247.9772 | H21: 94923.958 | L21: =IF('vertical grid'!B21>($C$2),0,'vertical grid'!D21) -> 19.666667 | N21: =IF(L22=0,IF(L21>0,1,0),0) -> 0 | P21: =N21*Y21 -> 0 | S21: =L21/$G$2 -> 96.426852 | U21: =L21/$G$3 -> 39.088439 | W21: =L21/$G$4 -> 58.087074 | Y21: =Vz!O21 -> 331.7848 | Z21: Time spent in error | AC21: =S21/Y21 -> 0.29063071 | AG21: =U21/Y21 -> 0.11781263 | AK21: =W21/Y21 -> 0.17507455
L22: =IF('vertical grid'!B22>($C$2),0,'vertical grid'!D22) -> 19.666667 | N22: =IF(L23=0,IF(L22>0,1,0),0) -> 0 | P22: =N22*Y22 -> 0 | S22: =L22/$G$2 -> 96.426852 | U22: =L22/$G$3 -> 39.088439 | W22: =L22/$G$4 -> 58.087074 | Y22: =Vz!O22 -> 331.7848 | Z22: distance, using | AC22: =S22/Y22 -> 0.29063071 | AG22: =U22/Y22 -> 0.11781263 | AK22: =W22/Y22 -> 0.17507455
H23: 55907.172 | L23: =IF('vertical grid'!B23>($C$2),0,'vertical grid'!D23) -> 101.66667 | N23: =IF(L24=0,IF(L23>0,1,0),0) -> 0 | P23: =N23*Y23 -> 0 | S23: =L23/$G$2 -> 498.47779 | U23: =L23/$G$3 -> 202.06735 | W23: =L23/$G$4 -> 300.28064 | Y23: =Vz!O23 -> 330.32827 | Z23: speed of sound at | AC23: =S23/Y23 -> 1.5090377 | AG23: =U23/Y23 -> 0.61171682 | AK23: =W23/Y23 -> 0.90903706
A24: Two-station comparator | H24: 61571.734 | L24: =IF('vertical grid'!B24>($C$2),0,'vertical grid'!D24) -> 101.66667 | N24: =IF(L25=0,IF(L24>0,1,0),0) -> 0 | P24: =N24*Y24 -> 0 | S24: =L24/$G$2 -> 498.47779 | U24: =L24/$G$3 -> 202.06735 | W24: =L24/$G$4 -> 300.28064 | Y24: =Vz!O24 -> 330.32827 | Z24: high altitude (s) | AC24: =S24/Y24 -> 1.5090377 | AG24: =U24/Y24 -> 0.61171682 | AK24: =W24/Y24 -> 0.90903706
H25: 95609.094 | L25: =IF('vertical grid'!B25>($C$2),0,'vertical grid'!D25) -> 101.66667 | N25: =IF(L26=0,IF(L25>0,1,0),0) -> 0 | P25: =N25*Y25 -> 0 | S25: =L25/$G$2 -> 498.47779 | U25: =L25/$G$3 -> 202.06735 | W25: =L25/$G$4 -> 300.28064 | Y25: =Vz!O25 -> 330.32827 | Z25: First seismometer | AA25: =AA6/O7 -> 97.919963 | AC25: =S25/Y25 -> 1.5090377 | AG25: =U25/Y25 -> 0.61171682 | AK25: =W25/Y25 -> 0.90903706
A26: Y47A | B26: t1 since midnight | C26: 81623 | D26: s --- long leg | L26: =IF('vertical grid'!B26>($C$2),0,'vertical grid'!D26) -> 30.333333 | N26: =IF(L27=0,IF(L26>0,1,0),0) -> 0 | P26: =N26*Y26 -> 0 | S26: =L26/$G$2 -> 148.72616 | U26: =L26/$G$3 -> 60.288948 | W26: =L26/$G$4 -> 89.591928 | Y26: =Vz!O26 -> 329.90223 | Z26: Second seismometer | AA26: =AA7/O7 -> 39.6937 | AC26: =S26/Y26 -> 0.4508189 | AG26: =U26/Y26 -> 0.18274793 | AK26: =W26/Y26 -> 0.27157115
A27: Y48A | B27: t2 since midnight | C27: 81521 | D27: s --- short leg | H27: 55907 | L27: =IF('vertical grid'!B27>($C$2),0,'vertical grid'!D27) -> 30.333333 | N27: =IF(L28=0,IF(L27>0,1,0),0) -> 0 | P27: =N27*Y27 -> 0 | S27: =L27/$G$2 -> 148.72616 | U27: =L27/$G$3 -> 60.288948 | W27: =L27/$G$4 -> 89.591928 | Y27: =Vz!O27 -> 329.90223 | Z27: Third seismometer | AA27: =AA8/O7 -> 58.986517 | AC27: =S27/Y27 -> 0.4508189 | AG27: =U27/Y27 -> 0.18274793 | AK27: =W27/Y27 -> 0.27157115
B28: h | C28: 30000 | D28: m | H28: 60575.5 | L28: =IF('vertical grid'!B28>($C$2),0,'vertical grid'!D28) -> 30.333333 | N28: =IF(L29=0,IF(L28>0,1,0),0) -> 0 | P28: =N28*Y28 -> 0 | S28: =L28/$G$2 -> 148.72616 | U28: =L28/$G$3 -> 60.288948 | W28: =L28/$G$4 -> 89.591928 | Y28: =Vz!O28 -> 329.90223 | AC28: =S28/Y28 -> 0.4508189 | AG28: =U28/Y28 -> 0.18274793 | AK28: =W28/Y28 -> 0.27157115
H29: 96605.5 | L29: =IF('vertical grid'!B29>($C$2),0,'vertical grid'!D29) -> 10 | N29: =IF(L30=0,IF(L29>0,1,0),0) -> 0 | P29: =N29*Y29 -> 0 | S29: =L29/$G$2 -> 49.030603 | U29: =L29/$G$3 -> 19.875478 | W29: =L29/$G$4 -> 29.5358 | Y29: =Vz!O29 -> 329.90223 | AC29: =S29/Y29 -> 0.14862162 | AG29: =U29/Y29 -> 0.060246569 | AK29: =W29/Y29 -> 0.08952895
B30: average speed of sound | C30: ='particle parameters'!B41 -> 318.85198 | D30: m/s | L30: =IF('vertical grid'!B30>($C$2),0,'vertical grid'!D30) -> 10 | N30: =IF(L31=0,IF(L30>0,1,0),0) -> 0 | P30: =N30*Y30 -> 0 | S30: =L30/$G$2 -> 49.030603 | U30: =L30/$G$3 -> 19.875478 | W30: =L30/$G$4 -> 29.5358 | Y30: =Vz!O30 -> 329.90223 | AC30: =S30/Y30 -> 0.14862162 | AG30: =U30/Y30 -> 0.060246569 | AK30: =W30/Y30 -> 0.08952895
B31: theta 1 | C31: 19.4 | D31: --- long leg | H31: 55699.396 | L31: =IF('vertical grid'!B31>($C$2),0,'vertical grid'!D31) -> 10 | N31: =IF(L32=0,IF(L31>0,1,0),0) -> 0 | P31: =N31*Y31 -> 0 | S31: =L31/$G$2 -> 49.030603 | U31: =L31/$G$3 -> 19.875478 | W31: =L31/$G$4 -> 29.5358 | Y31: =Vz!O31 -> 329.90223 | AC31: =S31/Y31 -> 0.14862162 | AG31: =U31/Y31 -> 0.060246569 | AK31: =W31/Y31 -> 0.08952895
B32: delta t between stations | C32: =C26-C27 -> 102 | D32: s | H32: 60118.271 | L32: =IF('vertical grid'!B32>($C$2),0,'vertical grid'!D32) -> 33 | N32: =IF(L33=0,IF(L32>0,1,0),0) -> 0 | P32: =N32*Y32 -> 0 | S32: =L32/$G$2 -> 161.80099 | U32: =L32/$G$3 -> 65.589076 | W32: =L32/$G$4 -> 97.468141 | Y32: =Vz!O32 -> 329.65854 | AC32: =S32/Y32 -> 0.49081389 | AG32: =U32/Y32 -> 0.19896065 | AK32: =W32/Y32 -> 0.29566394
B33: delta l between stations | C33: =C32*C30 -> 32522.902 | D33: m | H33: 97270.334 | L33: =IF('vertical grid'!B33>($C$2),0,'vertical grid'!D33) -> 33 | N33: =IF(L34=0,IF(L33>0,1,0),0) -> 0 | P33: =N33*Y33 -> 0 | S33: =L33/$G$2 -> 161.80099 | U33: =L33/$G$3 -> 65.589076 | W33: =L33/$G$4 -> 97.468141 | Y33: =Vz!O33 -> 329.65854 | AC33: =S33/Y33 -> 0.49081389 | AG33: =U33/Y33 -> 0.19896065 | AK33: =W33/Y33 -> 0.29566394
B34: Path length (L) | L34: =IF('vertical grid'!B34>($C$2),0,'vertical grid'!D34) -> 33 | N34: =IF(L35=0,IF(L34>0,1,0),0) -> 0 | P34: =N34*Y34 -> 0 | S34: =L34/$G$2 -> 161.80099 | U34: =L34/$G$3 -> 65.589076 | W34: =L34/$G$4 -> 97.468141 | Y34: =Vz!O34 -> 329.65854 | AC34: =S34/Y34 -> 0.49081389 | AG34: =U34/Y34 -> 0.19896065 | AK34: =W34/Y34 -> 0.29566394
B35: L1 | C35: =C36+C33 -> 90317.611 | D35: m | L35: =IF('vertical grid'!B35>($C$2),0,'vertical grid'!D35) -> 28.333333 | N35: =IF(L36=0,IF(L35>0,1,0),0) -> 0 | P35: =N35*Y35 -> 0 | S35: =L35/$G$2 -> 138.92004 | U35: =L35/$G$3 -> 56.313853 | W35: =L35/$G$4 -> 83.684768 | Y35: =Vz!O35 -> 329.23164 | AC35: =S35/Y35 -> 0.42195228 | AG35: =U35/Y35 -> 0.1710463 | AK35: =W35/Y35 -> 0.25418204
B36: L2 | C36: =(C28/(SIN(RADIANS(C31))))-C33 -> 57794.71 | D36: m | L36: =IF('vertical grid'!B36>($C$2),0,'vertical grid'!D36) -> 28.333333 | N36: =IF(L37=0,IF(L36>0,1,0),0) -> 0 | P36: =N36*Y36 -> 0 | S36: =L36/$G$2 -> 138.92004 | U36: =L36/$G$3 -> 56.313853 | W36: =L36/$G$4 -> 83.684768 | Y36: =Vz!O36 -> 329.23164 | AC36: =S36/Y36 -> 0.42195228 | AG36: =U36/Y36 -> 0.1710463 | AK36: =W36/Y36 -> 0.25418204
B37: Ground distance (d) | L37: =IF('vertical grid'!B37>($C$2),0,'vertical grid'!D37) -> 28.333333 | N37: =IF(L38=0,IF(L37>0,1,0),0) -> 0 | P37: =N37*Y37 -> 0 | S37: =L37/$G$2 -> 138.92004 | U37: =L37/$G$3 -> 56.313853 | W37: =L37/$G$4 -> 83.684768 | Y37: =Vz!O37 -> 329.23164 | AC37: =S37/Y37 -> 0.42195228 | AG37: =U37/Y37 -> 0.1710463 | AK37: =W37/Y37 -> 0.25418204
B38: d1 | C38: =SQRT((C35^2)-($C$28^2)) -> 85189.617 | L38: =IF('vertical grid'!B38>($C$2),0,'vertical grid'!D38) -> 101.33333 | N38: =IF(L39=0,IF(L38>0,1,0),0) -> 0 | P38: =N38*Y38 -> 0 | S38: =L38/$G$2 -> 496.84344 | U38: =L38/$G$3 -> 201.40484 | W38: =L38/$G$4 -> 299.29611 | Y38: =Vz!O38 -> 327.64114 | AC38: =S38/Y38 -> 1.5164257 | AG38: =U38/Y38 -> 0.6147117 | AK38: =W38/Y38 -> 0.91348759
B39: d2 | C39: =SQRT(ABS((C36^2)-(C28^2))) -> 49398.669 | L39: =IF('vertical grid'!B39>($C$2),0,'vertical grid'!D39) -> 101.33333 | N39: =IF(L40=0,IF(L39>0,1,0),0) -> 0 | P39: =N39*Y39 -> 0 | S39: =L39/$G$2 -> 496.84344 | U39: =L39/$G$3 -> 201.40484 | W39: =L39/$G$4 -> 299.29611 | Y39: =Vz!O39 -> 327.64114 | AC39: =S39/Y39 -> 1.5164257 | AG39: =U39/Y39 -> 0.6147117 | AK39: =W39/Y39 -> 0.91348759
B40: dtot CALCed | C40: =C38+C39 -> 134588.29 | D40: <-- make these values match | L40: =IF('vertical grid'!B40>($C$2),0,'vertical grid'!D40) -> 101.33333 | N40: =IF(L41=0,IF(L40>0,1,0),0) -> 0 | P40: =N40*Y40 -> 0 | S40: =L40/$G$2 -> 496.84344 | U40: =L40/$G$3 -> 201.40484 | W40: =L40/$G$4 -> 299.29611 | Y40: =Vz!O40 -> 327.64114 | AC40: =S40/Y40 -> 1.5164257 | AG40: =U40/Y40 -> 0.6147117 | AK40: =W40/Y40 -> 0.91348759
...

Sheet RAOB input
A1: =L1 -> 988 | B1: =M1 -> 229 | C1: =N1*10 -> 132 | D1: =O1 -> -2.8 | E1: =R1 -> 330 | F1: =(S1*0.51444)*10 -> 66.8772 | G1: Checklist: | H1: Delta-altitude ok? | I1: Negative value? | J1: =J2 -> 76 | K1: Paste here: | L1: 988 | M1: 229 | N1: 13.2 | O1: -2.8 | P1: 33 | Q1: 3.16 | R1: 330 | S1: 13 | T1: 287.3 | U1: 296.7 | V1: 287.9
A2: =L2 -> 979 | B2: =M2 -> 305 | C2: =N2*10 -> 125 | D2: =O2 -> -3.1 | E2: =R2 -> 330 | F2: =(S2*0.51444)*10 -> 66.8772 | G2: - valid T in first column? | H2: =IF((J2>500),1111111,0) -> 0 | I2: =IF((J2<0),1111111,0) -> 0 | J2: =B2-B1 -> 76 | L2: 979 | M2: 305 | N2: 12.5 | O2: -3.1 | P2: 34 | Q2: 3.13 | R2: 330 | S2: 13 | T2: 287.4 | U2: 296.6 | V2: 287.9
A3: =L3 -> 943.7 | B3: =M3 -> 610 | C3: =N3*10 -> 97 | D3: =O3 -> -4.2 | E3: =R3 -> 320 | F3: =(S3*0.51444)*10 -> 77.166 | G3: - all delta-z less than 500 tenths? | H3: =IF((J3>500),1111111,0) -> 0 | I3: =IF((J3<0),1111111,0) -> 0 | J3: =B3-B2 -> 305 | L3: 943.7 | M3: 610 | N3: 9.7 | O3: -4.2 | P3: 37 | Q3: 2.98 | R3: 320 | S3: 15 | T3: 287.6 | U3: 296.4 | V3: 288.1
A4: =L4 -> 925 | B4: =M4 -> 776 | C4: =N4*10 -> 82 | D4: =O4 -> -4.8 | E4: =R4 -> 315 | F4: =(S4*0.51444)*10 -> 77.166 | G4: - highest alt broken into ten slices? | H4: =IF((J4>500),1111111,0) -> 0 | I4: =IF((J4<0),1111111,0) -> 0 | J4: =B4-B3 -> 166 | L4: 925 | M4: 776 | N4: 8.2 | O4: -4.8 | P4: 39 | Q4: 2.91 | R4: 315 | S4: 15 | T4: 287.7 | U4: 296.3 | V4: 288.2
A5: =L5 -> 909.5 | B5: =M5 -> 914 | C5: =N5*10 -> 68 | D5: =O5 -> -5.2 | E5: =R5 -> 310 | F5: =(S5*0.51444)*10 -> 77.166 | H5: =IF((J5>500),1111111,0) -> 0 | I5: =IF((J5<0),1111111,0) -> 0 | J5: =B5-B4 -> 138 | L5: 909.5 | M5: 914 | N5: 6.8 | O5: -5.2 | P5: 42 | Q5: 2.87 | R5: 310 | S5: 15 | T5: 287.6 | U5: 296.2 | V5: 288.1
A6: =L6 -> 876 | B6: =M6 -> 1219 | C6: =N6*10 -> 37 | D6: =O6 -> -6.1 | E6: =R6 -> 305 | F6: =(S6*0.51444)*10 -> 72.0216 | H6: =IF((J6>500),1111111,0) -> 0 | I6: =IF((J6<0),1111111,0) -> 0 | J6: =B6-B5 -> 305 | L6: 876 | M6: 1219 | N6: 3.7 | O6: -6.1 | P6: 49 | Q6: 2.78 | R6: 305 | S6: 14 | T6: 287.5 | U6: 295.8 | V6: 288
A7: =L7 -> 850 | B7: =M7 -> 1465 | C7: =N7*10 -> 12 | D7: =O7 -> -6.8 | E7: =R7 -> 305 | F7: =(S7*0.51444)*10 -> 72.0216 | G7: By column: | H7: =IF((J7>500),1111111,0) -> 0 | I7: =IF((J7<0),1111111,0) -> 0 | J7: =B7-B6 -> 246 | L7: 850 | M7: 1465 | N7: 1.2 | O7: -6.8 | P7: 55 | Q7: 2.71 | R7: 305 | S7: 14 | T7: 287.4 | U7: 295.5 | V7: 287.9
A8: =L8 -> 843.8 | B8: =M8 -> 1524 | C8: =N8*10 -> 8 | D8: =O8 -> -6.8 | E8: =R8 -> 305 | F8: =(S8*0.51444)*10 -> 72.0216 | G8: (internal) | H8: =IF((J8>500),1111111,0) -> 0 | I8: =IF((J8<0),1111111,0) -> 0 | J8: =B8-B7 -> 59 | L8: 843.8 | M8: 1524 | N8: 0.8 | O8: -6.8 | P8: 57 | Q8: 2.73 | R8: 305 | S8: 14 | T8: 287.5 | U8: 295.7 | V8: 288
A9: =L9 -> 812.2 | B9: =M9 -> 1829 | C9: =N9*10 -> -16 | D9: =O9 -> -6.8 | E9: =R9 -> 310 | F9: =(S9*0.51444)*10 -> 92.5992 | G9: Pressure (hPa) | H9: =IF((J9>500),1111111,0) -> 0 | I9: =IF((J9<0),1111111,0) -> 0 | J9: =B9-B8 -> 305 | L9: 812.2 | M9: 1829 | N9: -1.6 | O9: -6.8 | P9: 68 | Q9: 2.84 | R9: 310 | S9: 18 | T9: 288.2 | U9: 296.6 | V9: 288.7
A10: =L10 -> 803 | B10: =M10 -> 1920 | C10: =N10*10 -> -23 | D10: =O10 -> -6.8 | E10: =R10 -> 311 | F10: =(S10*0.51444)*10 -> 102.888 | G10: Height (m) | H10: =IF((J10>500),1111111,0) -> 0 | I10: =IF((J10<0),1111111,0) -> 0 | J10: =B10-B9 -> 91 | L10: 803 | M10: 1920 | N10: -2.3 | O10: -6.8 | P10: 71 | Q10: 2.87 | R10: 311 | S10: 20 | T10: 288.4 | U10: 296.9 | V10: 288.9
A11: =L11 -> 800 | B11: =M11 -> 1950 | C11: =N11*10 -> -23 | D11: =O11 -> -17.3 | E11: =R11 -> 312 | F11: =(S11*0.51444)*10 -> 108.0324 | G11: Temp (tenths of C) | H11: =IF((J11>500),1111111,0) -> 0 | I11: =IF((J11<0),1111111,0) -> 0 | J11: =B11-B10 -> 30 | L11: 800 | M11: 1950 | N11: -2.3 | O11: -17.3 | P11: 31 | Q11: 1.24 | R11: 312 | S11: 21 | T11: 288.7 | U11: 292.6 | V11: 288.9
A12: =L12 -> 790 | B12: =M12 -> 2049 | C12: =N12*10 -> -27 | D12: =O12 -> -32.7 | E12: =R12 -> 314 | F12: =(S12*0.51444)*10 -> 118.3212 | G12: Dewpt | H12: =IF((J12>500),1111111,0) -> 0 | I12: =IF((J12<0),1111111,0) -> 0 | J12: =B12-B11 -> 99 | L12: 790 | M12: 2049 | N12: -2.7 | O12: -32.7 | P12: 8 | Q12: 0.31 | R12: 314 | S12: 23 | T12: 289.3 | U12: 290.4 | V12: 289.4
A13: =L13 -> 781.5 | B13: =M13 -> 2134 | C13: =N13*10 -> -34 | D13: =O13 -> -33.1 | E13: =R13 -> 315 | F13: =(S13*0.51444)*10 -> 128.61 | G13: Wind Dir (degrees) | H13: =IF((J13>500),1111111,0) -> 0 | I13: =IF((J13<0),1111111,0) -> 0 | J13: =B13-B12 -> 85 | L13: 781.5 | M13: 2134 | N13: -3.4 | O13: -33.1 | P13: 8 | Q13: 0.3 | R13: 315 | S13: 25 | T13: 289.4 | U13: 290.4 | V13: 289.5
A14: =L14 -> 751.6 | B14: =M14 -> 2438 | C14: =N14*10 -> -60 | D14: =O14 -> -34.8 | E14: =R14 -> 320 | F14: =(S14*0.51444)*10 -> 138.8988 | G14: Wind Speed (tenths of m/s) | H14: =IF((J14>500),1111111,0) -> 0 | I14: =IF((J14<0),1111111,0) -> 0 | J14: =B14-B13 -> 304 | L14: 751.6 | M14: 2438 | N14: -6 | O14: -34.8 | P14: 8 | Q14: 0.27 | R14: 320 | S14: 27 | T14: 289.9 | U14: 290.8 | V14: 289.9
A15: =L15 -> 722.8 | B15: =M15 -> 2743 | C15: =N15*10 -> -86 | D15: =O15 -> -36.4 | E15: =R15 -> 315 | F15: =(S15*0.51444)*10 -> 128.61 | H15: =IF((J15>500),1111111,0) -> 0 | I15: =IF((J15<0),1111111,0) -> 0 | J15: =B15-B14 -> 305 | L15: 722.8 | M15: 2743 | N15: -8.6 | O15: -36.4 | P15: 9 | Q15: 0.24 | R15: 315 | S15: 25 | T15: 290.3 | U15: 291.1 | V15: 290.3
A16: =L16 -> 700 | B16: =M16 -> 2993 | C16: =N16*10 -> -107 | D16: =O16 -> -37.7 | E16: =R16 -> 305 | F16: =(S16*0.51444)*10 -> 113.1768 | H16: =IF((J16>500),1111111,0) -> 0 | I16: =IF((J16<0),1111111,0) -> 0 | J16: =B16-B15 -> 250 | L16: 700 | M16: 2993 | N16: -10.7 | O16: -37.7 | P16: 9 | Q16: 0.21 | R16: 305 | S16: 22 | T16: 290.6 | U16: 291.4 | V16: 290.6
A17: =L17 -> 695 | B17: =M17 -> 3048 | C17: =N17*10 -> -112 | D17: =O17 -> -37.9 | E17: =R17 -> 295 | F17: =(S17*0.51444)*10 -> 118.3212 | H17: =IF((J17>500),1111111,0) -> 0 | I17: =IF((J17<0),1111111,0) -> 0 | J17: =B17-B16 -> 55 | L17: 695 | M17: 3048 | N17: -11.2 | O17: -37.9 | P17: 9 | Q17: 0.21 | R17: 295 | S17: 23 | T17: 290.7 | U17: 291.4 | V17: 290.7
A18: =L18 -> 663 | B18: =M18 -> 3408 | C18: =N18*10 -> -143 | D18: =O18 -> -39.3 | E18: =R18 -> 292 | F18: =(S18*0.51444)*10 -> 133.7544 | H18: =IF((J18>500),1111111,0) -> 0 | I18: =IF((J18<0),1111111,0) -> 0 | J18: =B18-B17 -> 360 | L18: 663 | M18: 3408 | N18: -14.3 | O18: -39.3 | P18: 10 | Q18: 0.19 | R18: 292 | S18: 26 | T18: 291.1 | U18: 291.8 | V18: 291.1
A19: =L19 -> 641.5 | B19: =M19 -> 3658 | C19: =N19*10 -> -155 | D19: =O19 -> -35.6 | E19: =R19 -> 290 | F19: =(S19*0.51444)*10 -> 144.0432 | H19: =IF((J19>500),1111111,0) -> 0 | I19: =IF((J19<0),1111111,0) -> 0 | J19: =B19-B18 -> 250 | L19: 641.5 | M19: 3658 | N19: -15.5 | O19: -35.6 | P19: 16 | Q19: 0.29 | R19: 290 | S19: 28 | T19: 292.5 | U19: 293.5 | V19: 292.6
A20: =L20 -> 641 | B20: =M20 -> 3664 | C20: =N20*10 -> -155 | D20: =O20 -> -35.5 | E20: =R20 -> 290 | F20: =(S20*0.51444)*10 -> 144.0432 | H20: =IF((J20>500),1111111,0) -> 0 | I20: =IF((J20<0),1111111,0) -> 0 | J20: =B20-B19 -> 6 | L20: 641 | M20: 3664 | N20: -15.5 | O20: -35.5 | P20: 16 | Q20: 0.29 | R20: 290 | S20: 28 | T20: 292.6 | U20: 293.6 | V20: 292.6
A21: =L21 -> 626 | B21: =M21 -> 3843 | C21: =N21*10 -> -137 | D21: =O21 -> -50.7 | E21: =R21 -> 289 | F21: =(S21*0.51444)*10 -> 154.332 | H21: =IF((J21>500),1111111,0) -> 0 | I21: =IF((J21<0),1111111,0) -> 0 | J21: =B21-B20 -> 179 | L21: 626 | M21: 3843 | N21: -13.7 | O21: -50.7 | P21: 3 | Q21: 0.06 | R21: 289 | S21: 30 | T21: 296.6 | U21: 296.8 | V21: 296.6
A22: =L22 -> 591.5 | B22: =M22 -> 4267 | C22: =N22*10 -> -171 | D22: =O22 -> -45.7 | E22: =R22 -> 285 | F22: =(S22*0.51444)*10 -> 169.7652 | H22: =IF((J22>500),1111111,0) -> 0 | I22: =IF((J22<0),1111111,0) -> 0 | J22: =B22-B21 -> 424 | L22: 591.5 | M22: 4267 | N22: -17.1 | O22: -45.7 | P22: 6 | Q22: 0.11 | R22: 285 | S22: 33 | T22: 297.4 | U22: 297.8 | V22: 297.4
A23: =L23 -> 567.8 | B23: =M23 -> 4572 | C23: =N23*10 -> -196 | D23: =O23 -> -42.1 | E23: =R23 -> 280 | F23: =(S23*0.51444)*10 -> 180.054 | H23: =IF((J23>500),1111111,0) -> 0 | I23: =IF((J23<0),1111111,0) -> 0 | J23: =B23-B22 -> 305 | L23: 567.8 | M23: 4572 | N23: -19.6 | O23: -42.1 | P23: 12 | Q23: 0.17 | R23: 280 | S23: 35 | T23: 298 | U23: 298.6 | V23: 298
A24: =L24 -> 545.1 | B24: =M24 -> 4877 | C24: =N24*10 -> -221 | D24: =O24 -> -38.5 | E24: =R24 -> 275 | F24: =(S24*0.51444)*10 -> 190.3428 | H24: =IF((J24>500),1111111,0) -> 0 | I24: =IF((J24<0),1111111,0) -> 0 | J24: =B24-B23 -> 305 | L24: 545.1 | M24: 4877 | N24: -22.1 | O24: -38.5 | P24: 21 | Q24: 0.25 | R24: 275 | S24: 37 | T24: 298.5 | U24: 299.4 | V24: 298.6
A25: =L25 -> 540 | B25: =M25 -> 4948 | C25: =N25*10 -> -227 | D25: =O25 -> -37.7 | E25: =R25 -> 273 | F25: =(S25*0.51444)*10 -> 200.6316 | H25: =IF((J25>500),1111111,0) -> 0 | I25: =IF((J25<0),1111111,0) -> 0 | J25: =B25-B24 -> 71 | L25: 540 | M25: 4948 | N25: -22.7 | O25: -37.7 | P25: 24 | Q25: 0.28 | R25: 273 | S25: 39 | T25: 298.7 | U25: 299.6 | V25: 298.7
A26: =L26 -> 514 | B26: =M26 -> 5309 | C26: =N26*10 -> -243 | D26: =O26 -> -52.3 | E26: =R26 -> 265 | F26: =(S26*0.51444)*10 -> 241.7868 | H26: =IF((J26>500),1111111,0) -> 0 | I26: =IF((J26<0),1111111,0) -> 0 | J26: =B26-B25 -> 361 | L26: 514 | M26: 5309 | N26: -24.3 | O26: -52.3 | P26: 6 | Q26: 0.06 | R26: 265 | S26: 47 | T26: 301 | U26: 301.2 | V26: 301
... A29: =L29 -> 460.9 | B29: =M29 -> 6096 | C29: =N29*10 -> -282 | D29: =O29 -> -57 | E29: =R29 -> 245 | F29: =(S29*0.51444)*10 -> 298.3752 | H29: =IF((J29>500),1111111,0) -> 0 | I29: =IF((J29<0),1111111,0) -> 0 | J29: =B29-B28 -> 92 | L29: 460.9 | M29: 6096 | N29: -28.2 | O29: -57 | P29: 5 | Q29: 0.04 | R29: 245 | S29: 58 | T29: 305.6 | U29: 305.8 | V29: 305.7
A30: 460.9 | B30: =B29+300 -> 6396 | C30: -282 | D30: -57 | E30: 245 | F30: 298.3752 | H30: =IF((J30>500),1111111,0) -> 0 | I30: =IF((J30<0),1111111,0) -> 0 | J30: =B30-B29 -> 300
A31: 400 | B31: =B30+300 -> 6696 | C31: -355 | D31: -62.5 | E31: 240 | F31: 360.108 | H31: =IF((J31>500),1111111,0) -> 0 | I31: =IF((J31<0),1111111,0) -> 0 | J31: =B31-B30 -> 300
A32: =L32 -> 400 | B32: =M32 -> 7100 | C32: =N32*10 -> -355 | D32: =O32 -> -62.5 | E32: =R32 -> 240 | F32: =(S32*0.51444)*10 -> 360.108 | H32: =IF((J32>500),1111111,0) -> 0 | I32: =IF((J32<0),1111111,0) -> 0 | J32: =B32-B31 -> 404 | L32: 400 | M32: 7100 | N32: -35.5 | O32: -62.5 | P32: 5 | Q32: 0.02 | R32: 240 | S32: 70 | T32: 308.8 | U32: 308.9 | V32: 308.8
A33: 370.5 | B33: =B32+300 -> 7400 | C33: -392 | D33: -61.7 | E33: 235 | F33: 421.8408 | H33: =IF((J33>500),1111111,0) -> 0 | I33: =IF((J33<0),1111111,0) -> 0 | J33: =B33-B32 -> 300
A34: =L34 -> 370.5 | B34: =M34 -> 7620 | C34: =N34*10 -> -392 | D34: =O34 -> -61.7 | E34: =R34 -> 235 | F34: =(S34*0.51444)*10 -> 421.8408 | H34: =IF((J34>500),1111111,0) -> 0 | I34: =IF((J34<0),1111111,0) -> 0 | J34: =B34-B33 -> 220 | L34: 370.5 | M34: 7620 | N34: -39.2 | O34: -61.7 | P34: 7 | Q34: 0.03 | R34: 235 | S34: 82 | T34: 310.8 | U34: 310.9 | V34: 310.8
A35: 338.6 | B35: =B34+300 -> 7920 | C35: -435 | D35: -60.7 | E35: 230 | F35: 478.4292 | H35: =IF((J35>500),1111111,0) -> 0 | I35: =IF((J35<0),1111111,0) -> 0 | J35: =B35-B34 -> 300
A36: =L36 -> 338.6 | B36: =M36 -> 8230 | C36: =N36*10 -> -435 | D36: =O36 -> -60.7 | E36: =R36 -> 230 | F36: =(S36*0.51444)*10 -> 478.4292 | H36: =IF((J36>500),1111111,0) -> 0 | I36: =IF((J36<0),1111111,0) -> 0 | J36: =B36-B35 -> 310 | L36: 338.6 | M36: 8230 | N36: -43.5 | O36: -60.7 | P36: 13 | Q36: 0.03 | R36: 230 | S36: 93 | T36: 313 | U36: 313.1 | V36: 313
A37: =L37 -> 315 | B37: =M37 -> 8719 | C37: =N37*10 -> -469 | D37: =O37 -> -59.9 | E37: =R37 -> 235 | F37: =(S37*0.51444)*10 -> 493.8624 | H37: =IF((J37>500),1111111,0) -> 0 | I37: =IF((J37<0),1111111,0) -> 0 | J37: =B37-B36 -> 489 | L37: 315 | M37: 8719 | N37: -46.9 | O37: -59.9 | P37: 21 | Q37: 0.04 | R37: 235 | S37: 96 | T37: 314.7 | U37: 314.9 | V37: 314.7
A38: =L38 -> 309.3 | B38: =M38 -> 8839 | C38: =N38*10 -> -477 | D38: =O38 -> -60.7 | E38: =R38 -> 235 | F38: =(S38*0.51444)*10 -> 473.2848 | H38: =IF((J38>500),1111111,0) -> 0 | I38: =IF((J38<0),1111111,0) -> 0 | J38: =B38-B37 -> 120 | L38: 309.3 | M38: 8839 | N38: -47.7 | O38: -60.7 | P38: 21 | Q38: 0.03 | R38: 235 | S38: 92 | T38: 315.2 | U38: 315.4 | V38: 315.2
A39: =L39 -> 300 | B39: =M39 -> 9040 | C39: =N39*10 -> -491 | D39: =O39 -> -62.1 | E39: =R39 -> 235 | F39: =(S39*0.51444)*10 -> 473.2848 | H39: =IF((J39>500),1111111,0) -> 0 | I39: =IF((J39<0),1111111,0) -> 0 | J39: =B39-B38 -> 201 | L39: 300 | M39: 9040 | N39: -49.1 | O39: -62.1 | P39: 20 | Q39: 0.03 | R39: 235 | S39: 92 | T39: 316 | U39: 316.2 | V39: 316
A40: =L40 -> 295.2 | B40: =M40 -> 9144 | C40: =N40*10 -> -498 | D40: =O40 -> -62.8 | E40: =R40 -> 235 | F40: =(S40*0.51444)*10 -> 468.1404 | H40: =IF((J40>500),1111111,0) -> 0 | I40: =IF((J40<0),1111111,0) -> 0 | J40: =B40-B39 -> 104 | L40: 295.2 | M40: 9144 | N40: -49.8 | O40: -62.8 | P40: 20 | Q40: 0.03 | R40: 235 | S40: 91 | T40: 316.6 | U40: 316.7 | V40: 316.6
A41: 256.3 | B41: =B40+300 -> 9444 | C41: -555 | D41: -69.3 | E41: 235 | F41: 447.5628 | H41: =IF((J41>500),1111111,0) -> 0 | I41: =IF((J41<0),1111111,0) -> 0 | J41: =B41-B40 -> 300
A42: 256.3 | B42: =B41+300 -> 9744 | C42: -555 | D42: -69.3 | E42: 235 | F42: 447.5628 | H42: =IF((J42>500),1111111,0) -> 0 | I42: =IF((J42<0),1111111,0) -> 0 | J42: =B42-B41 -> 300
...

Sheet RAOB interpolated
A1: Triple-expanded | B1: =I1 -> 988 | C1: =IF(B1>0,J1,0) -> 229 | D1: =K1 -> 132 | E1: =L1 -> -2.8 | F1: =M1 -> 330 | G1: =N1 -> 66.8772 | H1: Re-space | I1: ='RAOB input'!A1 -> 988 | J1: ='RAOB input'!B1 -> 229 | K1: ='RAOB input'!C1 -> 132 | L1: ='RAOB input'!D1 -> -2.8 | M1: ='RAOB input'!E1 -> 330 | N1: ='RAOB input'!F1 -> 66.8772
A2: USE THESE VALUES | B2: =I4 -> 979 | C2: =C1+((C4-C1)/3) -> 254.33333 | D2: =K4 -> 125 | E2: =L4 -> -3.1 | F2: =M4 -> 330 | G2: =N4 -> 66.8772
B3: =B2 -> 979 | C3: =C1+(2*(C2-C1)) -> 279.66667 | D3: =D2 -> 125 | E3: =E2 -> -3.1 | F3: =F2 -> 330 | G3: =G2 -> 66.8772
A4: DO NOT USE THE | B4: =B2 -> 979 | C4: =J4 -> 305 | D4: =D2 -> 125 | E4: =E2 -> -3.1 | F4: =F2 -> 330 | G4: =G2 -> 66.8772 | I4: ='RAOB input'!A2 -> 979 | J4: ='RAOB input'!B2 -> 305 | K4: ='RAOB input'!C2 -> 125 | L4: ='RAOB input'!D2 -> -3.1 | M4: ='RAOB input'!E2 -> 330 | N4: ='RAOB input'!F2 -> 66.8772
A5: BOTTOM TWO LINES | B5: =I7 -> 943.7 | C5: =C4+((C7-C4)/3) -> 406.66667 | D5: =K7 -> 97 | E5: =L7 -> -4.2 | F5: =M7 -> 320 | G5: =N7 -> 77.166
B6: =B5 -> 943.7 | C6: =C4+(2*(C5-C4)) -> 508.33333 | D6: =D5 -> 97 | E6: =E5 -> -4.2 | F6: =F5 -> 320 | G6: =G5 -> 77.166
B7: =B5 -> 943.7 | C7: =J7 -> 610 | D7: =D5 -> 97 | E7: =E5 -> -4.2 | F7: =F5 -> 320 | G7: =G5 -> 77.166 | I7: ='RAOB input'!A3 -> 943.7 | J7: ='RAOB input'!B3 -> 610 | K7: ='RAOB input'!C3 -> 97 | L7: ='RAOB input'!D3 -> -4.2 | M7: ='RAOB input'!E3 -> 320 | N7: ='RAOB input'!F3 -> 77.166
B8: =I10 -> 925 | C8: =C7+((C10-C7)/3) -> 665.33333 | D8: =K10 -> 82 | E8: =L10 -> -4.8 | F8: =M10 -> 315 | G8: =N10 -> 77.166
B9: =B8 -> 925 | C9: =C7+(2*(C8-C7)) -> 720.66667 | D9: =D8 -> 82 | E9: =E8 -> -4.8 | F9: =F8 -> 315 | G9: =G8 -> 77.166
B10: =B8 -> 925 | C10: =J10 -> 776 | D10: =D8 -> 82 | E10: =E8 -> -4.8 | F10: =F8 -> 315 | G10: =G8 -> 77.166 | I10: ='RAOB input'!A4 -> 925 | J10: ='RAOB input'!B4 -> 776 | K10: ='RAOB input'!C4 -> 82 | L10: ='RAOB input'!D4 -> -4.8 | M10: ='RAOB input'!E4 -> 315 | N10: ='RAOB input'!F4 -> 77.166
B11: =I13 -> 909.5 | C11: =C10+((C13-C10)/3) -> 822 | D11: =K13 -> 68 | E11: =L13 -> -5.2 | F11: =M13 -> 310 | G11: =N13 -> 77.166
B12: =B11 -> 909.5 | C12: =C10+(2*(C11-C10)) -> 868 | D12: =D11 -> 68 | E12: =E11 -> -5.2 | F12: =F11 -> 310 | G12: =G11 -> 77.166
B13: =B11 -> 909.5 | C13: =J13 -> 914 | D13: =D11 -> 68 | E13: =E11 -> -5.2 | F13: =F11 -> 310 | G13: =G11 -> 77.166 | H13: 5 | I13: ='RAOB input'!A5 -> 909.5 | J13: ='RAOB input'!B5 -> 914 | K13: ='RAOB input'!C5 -> 68 | L13: ='RAOB input'!D5 -> -5.2 | M13: ='RAOB input'!E5 -> 310 | N13: ='RAOB input'!F5 -> 77.166
B14: =I16 -> 876 | C14: =C13+((C16-C13)/3) -> 1015.6667 | D14: =K16 -> 37 | E14: =L16 -> -6.1 | F14: =M16 -> 305 | G14: =N16 -> 72.0216
B15: =B14 -> 876 | C15: =C13+(2*(C14-C13)) -> 1117.3333 | D15: =D14 -> 37 | E15: =E14 -> -6.1 | F15: =F14 -> 305 | G15: =G14 -> 72.0216
B16: =B14 -> 876 | C16: =J16 -> 1219 | D16: =D14 -> 37 | E16: =E14 -> -6.1 | F16: =F14 -> 305 | G16: =G14 -> 72.0216 | I16: ='RAOB input'!A6 -> 876 | J16: ='RAOB input'!B6 -> 1219 | K16: ='RAOB input'!C6 -> 37 | L16: ='RAOB input'!D6 -> -6.1 | M16: ='RAOB input'!E6 -> 305 | N16: ='RAOB input'!F6 -> 72.0216
B17: =I19 -> 850 | C17: =C16+((C19-C16)/3) -> 1301 | D17: =K19 -> 12 | E17: =L19 -> -6.8 | F17: =M19 -> 305 | G17: =N19 -> 72.0216
B18: =B17 -> 850 | C18: =C16+(2*(C17-C16)) -> 1383 | D18: =D17 -> 12 | E18: =E17 -> -6.8 | F18: =F17 -> 305 | G18: =G17 -> 72.0216
B19: =B17 -> 850 | C19: =J19 -> 1465 | D19: =D17 -> 12 | E19: =E17 -> -6.8 | F19: =F17 -> 305 | G19: =G17 -> 72.0216 | I19: ='RAOB input'!A7 -> 850 | J19: ='RAOB input'!B7 -> 1465 | K19: ='RAOB input'!C7 -> 12 | L19: ='RAOB input'!D7 -> -6.8 | M19: ='RAOB input'!E7 -> 305 | N19: ='RAOB input'!F7 -> 72.0216
B20: =I22 -> 843.8 | C20: =C19+((C22-C19)/3) -> 1484.6667 | D20: =K22 -> 8 | E20: =L22 -> -6.8 | F20: =M22 -> 305 | G20: =N22 -> 72.0216
B21: =B20 -> 843.8 | C21: =C19+(2*(C20-C19)) -> 1504.3333 | D21: =D20 -> 8 | E21: =E20 -> -6.8 | F21: =F20 -> 305 | G21: =G20 -> 72.0216
B22: =B20 -> 843.8 | C22: =J22 -> 1524 | D22: =D20 -> 8 | E22: =E20 -> -6.8 | F22: =F20 -> 305 | G22: =G20 -> 72.0216 | I22: ='RAOB input'!A8 -> 843.8 | J22: ='RAOB input'!B8 -> 1524 | K22: ='RAOB input'!C8 -> 8 | L22: ='RAOB input'!D8 -> -6.8 | M22: ='RAOB input'!E8 -> 305 | N22: ='RAOB input'!F8 -> 72.0216
B23: =I25 -> 812.2 | C23: =C22+((C25-C22)/3) -> 1625.6667 | D23: =K25 -> -16 | E23: =L25 -> -6.8 | F23: =M25 -> 310 | G23: =N25 -> 92.5992
B24: =B23 -> 812.2 | C24: =C22+(2*(C23-C22)) -> 1727.3333 | D24: =D23 -> -16 | E24: =E23 -> -6.8 | F24: =F23 -> 310 | G24: =G23 -> 92.5992
B25: =B23 -> 812.2 | C25: =J25 -> 1829 | D25: =D23 -> -16 | E25: =E23 -> -6.8 | F25: =F23 -> 310 | G25: =G23 -> 92.5992 | I25: ='RAOB input'!A9 -> 812.2 | J25: ='RAOB input'!B9 -> 1829 | K25: ='RAOB input'!C9 -> -16 | L25: ='RAOB input'!D9 -> -6.8 | M25: ='RAOB input'!E9 -> 310 | N25: ='RAOB input'!F9 -> 92.5992
B26: =I28 -> 803 | C26: =C25+((C28-C25)/3) -> 1859.3333 | D26: =K28 -> -23 | E26: =L28 -> -6.8 | F26: =M28 -> 311 | G26: =N28 -> 102.888
B27: =B26 -> 803 | C27: =C25+(2*(C26-C25)) -> 1889.6667 | D27: =D26 -> -23 | E27: =E26 -> -6.8 | F27: =F26 -> 311 | G27: =G26 -> 102.888
B28: =B26 -> 803 | C28: =J28 -> 1920 | D28: =D26 -> -23 | E28: =E26 -> -6.8 | F28: =F26 -> 311 | G28: =G26 -> 102.888 | H28: 10 | I28: ='RAOB input'!A10 -> 803 | J28: ='RAOB input'!B10 -> 1920 | K28: ='RAOB input'!C10 -> -23 | L28: ='RAOB input'!D10 -> -6.8 | M28: ='RAOB input'!E10 -> 311 | N28: ='RAOB input'!F10 -> 102.888
B29: =I31 -> 800 | C29: =C28+((C31-C28)/3) -> 1930 | D29: =K31 -> -23 | E29: =L31 -> -17.3 | F29: =M31 -> 312 | G29: =N31 -> 108.0324
B30: =B29 -> 800 | C30: =C28+(2*(C29-C28)) -> 1940 | D30: =D29 -> -23 | E30: =E29 -> -17.3 | F30: =F29 -> 312 | G30: =G29 -> 108.0324
B31: =B29 -> 800 | C31: =J31 -> 1950 | D31: =D29 -> -23 | E31: =E29 -> -17.3 | F31: =F29 -> 312 | G31: =G29 -> 108.0324 | I31: ='RAOB input'!A11 -> 800 | J31: ='RAOB input'!B11 -> 1950 | K31: ='RAOB input'!C11 -> -23 | L31: ='RAOB input'!D11 -> -17.3 | M31: ='RAOB input'!E11 -> 312 | N31: ='RAOB input'!F11 -> 108.0324
B32: =I34 -> 790 | C32: =C31+((C34-C31)/3) -> 1983 | D32: =K34 -> -27 | E32: =L34 -> -32.7 | F32: =M34 -> 314 | G32: =N34 -> 118.3212
B33: =B32 -> 790 | C33: =C31+(2*(C32-C31)) -> 2016 | D33: =D32 -> -27 | E33: =E32 -> -32.7 | F33: =F32 -> 314 | G33: =G32 -> 118.3212
B34: =B32 -> 790 | C34: =J34 -> 2049 | D34: =D32 -> -27 | E34: =E32 -> -32.7 | F34: =F32 -> 314 | G34: =G32 -> 118.3212 | I34: ='RAOB input'!A12 -> 790 | J34: ='RAOB input'!B12 -> 2049 | K34: ='RAOB input'!C12 -> -27 | L34: ='RAOB input'!D12 -> -32.7 | M34: ='RAOB input'!E12 -> 314 | N34: ='RAOB input'!F12 -> 118.3212
B35: =I37 -> 781.5 | C35: =C34+((C37-C34)/3) -> 2077.3333 | D35: =K37 -> -34 | E35: =L37 -> -33.1 | F35: =M37 -> 315 | G35: =N37 -> 128.61
B36: =B35 -> 781.5 | C36: =C34+(2*(C35-C34)) -> 2105.6667 | D36: =D35 -> -34 | E36: =E35 -> -33.1 | F36: =F35 -> 315 | G36: =G35 -> 128.61
B37: =B35 -> 781.5 | C37: =J37 -> 2134 | D37: =D35 -> -34 | E37: =E35 -> -33.1 | F37: =F35 -> 315 | G37: =G35 -> 128.61 | I37: ='RAOB input'!A13 -> 781.5 | J37: ='RAOB input'!B13 -> 2134 | K37: ='RAOB input'!C13 -> -34 | L37: ='RAOB input'!D13 -> -33.1 | M37: ='RAOB input'!E13 -> 315 | N37: ='RAOB input'!F13 -> 128.61
B38: =I40 -> 751.6 | C38: =C37+((C40-C37)/3) -> 2235.3333 | D38: =K40 -> -60 | E38: =L40 -> -34.8 | F38: =M40 -> 320 | G38: =N40 -> 138.8988
B39: =B38 -> 751.6 | C39: =C37+(2*(C38-C37)) -> 2336.6667 | D39: =D38 -> -60 | E39: =E38 -> -34.8 | F39: =F38 -> 320 | G39: =G38 -> 138.8988
B40: =B38 -> 751.6 | C40: =J40 -> 2438 | D40: =D38 -> -60 | E40: =E38 -> -34.8 | F40: =F38 -> 320 | G40: =G38 -> 138.8988 | I40: ='RAOB input'!A14 -> 751.6 | J40: ='RAOB input'!B14 -> 2438 | K40: ='RAOB input'!C14 -> -60 | L40: ='RAOB input'!D14 -> -34.8 | M40: ='RAOB input'!E14 -> 320 | N40: ='RAOB input'!F14 -> 138.8988
...

Sheet RAOB Used for Calcs
B1: 988 | C1: 229 | D1: 132 | E1: -2.8 | F1: 330 | G1: 66.8772 | H1: Checklist: | I1: Delta-altitude>500? | J1: =J2 -> 25.333333 | K1: (counter) | L1: =(IF(C2>0,1,0))+(IF(C3>0,-1,0)) -> 0 | M1: (counter) | N1: =IF(C2>0,1,0) -> 1 | P1: altitude (m) | Q1: =IF(C1=0, C1/0, C1) -> 229 | R1: direction (degrees) | S1: =IF(F1=0, F1/0, F1) -> 330 | T1: wind speed (m/s) | U1: =IF(G1=0, G1/0, G1/10) -> 6.68772
B2: 979 | C2: 254.33333 | D2: 125 | E2: -3.1 | F2: 330 | G2: 66.8772 | H2: - valid T in first column? | I2: =IF((J2>500),1111111,0) -> 0 | J2: =C2-C1 -> 25.333333 | L2: =(IF(C2>0,1,0))+(IF(C3>0,-1,0)) -> 0 | N2: =IF(C2>0,1,0) -> 1 | Q2: =IF(C2=0, C2/0, C2) -> 254.33333 | S2: =IF(F2=0, F2/0, F2) -> 330 | U2: =IF(G2=0, G2/0, G2/10) -> 6.68772
B3: 979 | C3: 279.66667 | D3: 125 | E3: -3.1 | F3: 330 | G3: 66.8772 | H3: - all delta-z less than 500 tenths? | I3: =IF((J3>500),1111111,0) -> 0 | J3: =C3-C2 -> 25.333333 | L3: =(IF(C3>0,1,0))+(IF(C4>0,-1,0)) -> 0 | N3: =IF(C3>0,1,0) -> 1 | Q3: =IF(C3=0, C3/0, C3) -> 279.66667 | S3: =IF(F3=0, F3/0, F3) -> 330 | U3: =IF(G3=0, G3/0, G3/10) -> 6.68772
B4: 979 | C4: 305 | D4: 125 | E4: -3.1 | F4: 330 | G4: 66.8772 | H4: - highest alt broken into ten slices? | I4: =IF((J4>500),1111111,0) -> 0 | J4: =C4-C3 -> 25.333333 | L4: =(IF(C4>0,1,0))+(IF(C5>0,-1,0)) -> 0 | N4: =IF(C4>0,1,0) -> 1 | Q4: =IF(C4=0, C4/0, C4) -> 305 | S4: =IF(F4=0, F4/0, F4) -> 330 | U4: =IF(G4=0, G4/0, G4/10) -> 6.68772
B5: 943.7 | C5: 406.66667 | D5: 97 | E5: -4.2 | F5: 320 | G5: 77.166 | I5: =IF((J5>500),1111111,0) -> 0 | J5: =C5-C4 -> 101.66667 | L5: =(IF(C5>0,1,0))+(IF(C6>0,-1,0)) -> 0 | N5: =IF(C5>0,1,0) -> 1 | Q5: =IF(C5=0, C5/0, C5) -> 406.66667 | S5: =IF(F5=0, F5/0, F5) -> 320 | U5: =IF(G5=0, G5/0, G5/10) -> 7.7166
B6: 943.7 | C6: 508.33333 | D6: 97 | E6: -4.2 | F6: 320 | G6: 77.166 | I6: =IF((J6>500),1111111,0) -> 0 | J6: =C6-C5 -> 101.66667 | L6: =(IF(C6>0,1,0))+(IF(C7>0,-1,0)) -> 0 | N6: =IF(C6>0,1,0) -> 1 | Q6: =IF(C6=0, C6/0, C6) -> 508.33333 | S6: =IF(F6=0, F6/0, F6) -> 320 | U6: =IF(G6=0, G6/0, G6/10) -> 7.7166
B7: 943.7 | C7: 610 | D7: 97 | E7: -4.2 | F7: 320 | G7: 77.166 | H7: By column: | I7: =IF((J7>500),1111111,0) -> 0 | J7: =C7-C6 -> 101.66667 | L7: =(IF(C7>0,1,0))+(IF(C8>0,-1,0)) -> 0 | N7: =IF(C7>0,1,0) -> 1 | Q7: =IF(C7=0, C7/0, C7) -> 610 | S7: =IF(F7=0, F7/0, F7) -> 320 | U7: =IF(G7=0, G7/0, G7/10) -> 7.7166
B8: 925 | C8: 665.33333 | D8: 82 | E8: -4.8 | F8: 315 | G8: 77.166 | H8: (internal) | I8: =IF((J8>500),1111111,0) -> 0 | J8: =C8-C7 -> 55.333333 | L8: =(IF(C8>0,1,0))+(IF(C9>0,-1,0)) -> 0 | N8: =IF(C8>0,1,0) -> 1 | Q8: =IF(C8=0, C8/0, C8) -> 665.33333 | S8: =IF(F8=0, F8/0, F8) -> 315 | U8: =IF(G8=0, G8/0, G8/10) -> 7.7166
B9: 925 | C9: 720.66667 | D9: 82 | E9: -4.8 | F9: 315 | G9: 77.166 | H9: Pressure (hPa) | I9: =IF((J9>500),1111111,0) -> 0 | J9: =C9-C8 -> 55.333333 | L9: =(IF(C9>0,1,0))+(IF(C10>0,-1,0)) -> 0 | N9: =IF(C9>0,1,0) -> 1 | Q9: =IF(C9=0, C9/0, C9) -> 720.66667 | S9: =IF(F9=0, F9/0, F9) -> 315 | U9: =IF(G9=0, G9/0, G9/10) -> 7.7166
B10: 925 | C10: 776 | D10: 82 | E10: -4.8 | F10: 315 | G10: 77.166 | H10: Height (m) | I10: =IF((J10>500),1111111,0) -> 0 | J10: =C10-C9 -> 55.333333 | L10: =(IF(C10>0,1,0))+(IF(C11>0,-1,0)) -> 0 | N10: =IF(C10>0,1,0) -> 1 | Q10: =IF(C10=0, C10/0, C10) -> 776 | S10: =IF(F10=0, F10/0, F10) -> 315 | U10: =IF(G10=0, G10/0, G10/10) -> 7.7166
B11: 909.5 | C11: 822 | D11: 68 | E11: -5.2 | F11: 310 | G11: 77.166 | H11: Temp (tenths of C) | I11: =IF((J11>500),1111111,0) -> 0 | J11: =C11-C10 -> 46 | L11: =(IF(C11>0,1,0))+(IF(C12>0,-1,0)) -> 0 | N11: =IF(C11>0,1,0) -> 1 | Q11: =IF(C11=0, C11/0, C11) -> 822 | S11: =IF(F11=0, F11/0, F11) -> 310 | U11: =IF(G11=0, G11/0, G11/10) -> 7.7166
B12: 909.5 | C12: 868 | D12: 68 | E12: -5.2 | F12: 310 | G12: 77.166 | H12: Dewpt | I12: =IF((J12>500),1111111,0) -> 0 | J12: =C12-C11 -> 46 | L12: =(IF(C12>0,1,0))+(IF(C13>0,-1,0)) -> 0 | N12: =IF(C12>0,1,0) -> 1 | Q12: =IF(C12=0, C12/0, C12) -> 868 | S12: =IF(F12=0, F12/0, F12) -> 310 | U12: =IF(G12=0, G12/0, G12/10) -> 7.7166
B13: 909.5 | C13: 914 | D13: 68 | E13: -5.2 | F13: 310 | G13: 77.166 | H13: Wind Dir (degrees) | I13: =IF((J13>500),1111111,0) -> 0 | J13: =C13-C12 -> 46 | L13: =(IF(C13>0,1,0))+(IF(C14>0,-1,0)) -> 0 | N13: =IF(C13>0,1,0) -> 1 | Q13: =IF(C13=0, C13/0, C13) -> 914 | S13: =IF(F13=0, F13/0, F13) -> 310 | U13: =IF(G13=0, G13/0, G13/10) -> 7.7166
B14: 876 | C14: 1015.6667 | D14: 37 | E14: -6.1 | F14: 305 | G14: 72.0216 | H14: Wind Speed (tenths of m/s) | I14: =IF((J14>500),1111111,0) -> 0 | J14: =C14-C13 -> 101.66667 | L14: =(IF(C14>0,1,0))+(IF(C15>0,-1,0)) -> 0 | N14: =IF(C14>0,1,0) -> 1 | Q14: =IF(C14=0, C14/0, C14) -> 1015.6667 | S14: =IF(F14=0, F14/0, F14) -> 305 | U14: =IF(G14=0, G14/0, G14/10) -> 7.20216
B15: 876 | C15: 1117.3333 | D15: 37 | E15: -6.1 | F15: 305 | G15: 72.0216 | I15: =IF((J15>500),1111111,0) -> 0 | J15: =C15-C14 -> 101.66667 | L15: =(IF(C15>0,1,0))+(IF(C16>0,-1,0)) -> 0 | N15: =IF(C15>0,1,0) -> 1 | Q15: =IF(C15=0, C15/0, C15) -> 1117.3333 | S15: =IF(F15=0, F15/0, F15) -> 305 | U15: =IF(G15=0, G15/0, G15/10) -> 7.20216
B16: 876 | C16: 1219 | D16: 37 | E16: -6.1 | F16: 305 | G16: 72.0216 | I16: =IF((J16>500),1111111,0) -> 0 | J16: =C16-C15 -> 101.66667 | L16: =(IF(C16>0,1,0))+(IF(C17>0,-1,0)) -> 0 | N16: =IF(C16>0,1,0) -> 1 | Q16: =IF(C16=0, C16/0, C16) -> 1219 | S16: =IF(F16=0, F16/0, F16) -> 305 | U16: =IF(G16=0, G16/0, G16/10) -> 7.20216
B17: 850 | C17: 1301 | D17: 12 | E17: -6.8 | F17: 305 | G17: 72.0216 | I17: =IF((J17>500),1111111,0) -> 0 | J17: =C17-C16 -> 82 | L17: =(IF(C17>0,1,0))+(IF(C18>0,-1,0)) -> 0 | N17: =IF(C17>0,1,0) -> 1 | Q17: =IF(C17=0, C17/0, C17) -> 1301 | S17: =IF(F17=0, F17/0, F17) -> 305 | U17: =IF(G17=0, G17/0, G17/10) -> 7.20216
